Traceback (most recent call last):
  File "/Users/irenezhang/Library/Caches/pypoetry/virtualenvs/cipher-yz4286-iL-mLfvo-py3.9/lib/python3.9/site-packages/jupyter_cache/executors/utils.py", line 58, in single_nb_execution
    executenb(
  File "/Users/irenezhang/Library/Caches/pypoetry/virtualenvs/cipher-yz4286-iL-mLfvo-py3.9/lib/python3.9/site-packages/nbclient/client.py", line 1204, in execute
    return NotebookClient(nb=nb, resources=resources, km=km, **kwargs).execute()
  File "/Users/irenezhang/Library/Caches/pypoetry/virtualenvs/cipher-yz4286-iL-mLfvo-py3.9/lib/python3.9/site-packages/nbclient/util.py", line 84, in wrapped
    return just_run(coro(*args, **kwargs))
  File "/Users/irenezhang/Library/Caches/pypoetry/virtualenvs/cipher-yz4286-iL-mLfvo-py3.9/lib/python3.9/site-packages/nbclient/util.py", line 62, in just_run
    return loop.run_until_complete(coro)
  File "/usr/local/Cellar/python@3.9/3.9.15/Frameworks/Python.framework/Versions/3.9/lib/python3.9/asyncio/base_events.py", line 647, in run_until_complete
    return future.result()
  File "/Users/irenezhang/Library/Caches/pypoetry/virtualenvs/cipher-yz4286-iL-mLfvo-py3.9/lib/python3.9/site-packages/nbclient/client.py", line 663, in async_execute
    await self.async_execute_cell(
  File "/Users/irenezhang/Library/Caches/pypoetry/virtualenvs/cipher-yz4286-iL-mLfvo-py3.9/lib/python3.9/site-packages/nbclient/client.py", line 965, in async_execute_cell
    await self._check_raise_for_error(cell, cell_index, exec_reply)
  File "/Users/irenezhang/Library/Caches/pypoetry/virtualenvs/cipher-yz4286-iL-mLfvo-py3.9/lib/python3.9/site-packages/nbclient/client.py", line 862, in _check_raise_for_error
    raise CellExecutionError.from_cell_and_msg(cell, exec_reply_content)
nbclient.exceptions.CellExecutionError: An error occurred while executing the following cell:
------------------
import cipher_yz4286

print(cipher_yz4286.__version__)
------------------

[0;31m---------------------------------------------------------------------------[0m
[0;31mModuleNotFoundError[0m                       Traceback (most recent call last)
Cell [0;32mIn [1], line 1[0m
[0;32m----> 1[0m [38;5;28;01mimport[39;00m [38;5;21;01mcipher_yz4286[39;00m
[1;32m      3[0m [38;5;28mprint[39m(cipher_yz4286[38;5;241m.[39m__version__)

[0;31mModuleNotFoundError[0m: No module named 'cipher_yz4286'
ModuleNotFoundError: No module named 'cipher_yz4286'

